const numerator = 100, dinominator = 'a';
try {
    console.log(numerator/dinominator);
 console.log(a);
}
catch(error){
 console.log('An error caught')
 console.log('Error message:'+error);
}
finally{
    console.log("finally block always executed")
}

